<?xml version="1.0" ?><!-- =================================================================================== --><!-- |    This document was autogenerated by xacro from /pomodo/install/xarm7_description/share/xarm7_description/urdf/robots/xarm7_with_camera.urdf.xacro | --><!-- |    EDITING THIS FILE BY HAND IS NOT RECOMMENDED                                 | --><!-- =================================================================================== --><robot name="xarm7"><material name="aluminum"><color rgba="0.5 0.5 0.5 1"/></material><material name="plastic"><color rgba="0.1 0.1 0.1 1"/></material><material name="zed_mat"><color rgba="0.8 0.8 0.8 1.0"/></material><material name="zedm_mat"><color rgba="0 0 0 1.0"/></material><material name="zed2_mat"><color rgba="0.25 0.25 0.25 1.0"/></material><material name="zed2i_mat"><color rgba="0.25 0.25 0.25 1.0"/></material><material name="zedx_mat"><color rgba="0.25 0.25 0.25 1.0"/></material><material name="zedxm_mat"><color rgba="0.25 0.25 0.25 1.0"/></material><material name="virtual_mat"><color rgba="0.25 0.25 0.25 1.0"/></material><material name="zedxonegs_mat"><color rgba="0.25 0.25 0.25 1.0"/></material><material name="zedxone4k_mat"><color rgba="0.25 0.25 0.25 1.0"/></material><link name="base_link"/><material name="xarm7_Black"><color rgba="0.0 0.0 0.0 1.0"/></material><material name="xarm7_Red"><color rgba="0.8 0.0 0.0 1.0"/></material><material name="xarm7_White"><color rgba="1.0 1.0 1.0 1.0"/></material><material name="xarm7_Silver"><color rgba="0.753 0.753 0.753 1.0"/></material><link name="xarm7_link_base"><inertial><origin rpy="0 0 0" xyz="-0.021131 -0.0016302 0.056488"/><mass value="0.88556"/><inertia ixx="0.0030595" ixy="0.00012259" ixz="-0.00062705" iyy="0.0037783" iyz="0.00027023" izz="0.0020125"/></inertial><visual><origin rpy="0 0 0" xyz="0 0 0"/><geometry><!-- <mesh filename="package://xarm7_description/meshes/link_base.STL" /> --><mesh filename="package://xarm7_description/meshes/link_base.STL"/></geometry><material name="xarm7_White"/></visual><collision><origin rpy="0 0 0" xyz="0 0 0"/><geometry><!-- <mesh filename="package://xarm7_description/meshes/link_base.STL" /> --><mesh filename="package://xarm7_description/meshes/link_base.STL"/></geometry></collision></link><joint name="xarm7_joint_base" type="fixed"><origin rpy="0 0 0" xyz="0 0 0"/><parent link="base_link"/><child link="xarm7_link_base"/></joint><link name="xarm7_link1"><inertial><origin rpy="0 0 0" xyz="-0.0042142 0.02821 -0.0087788"/><mass value="0.42603"/><inertia ixx="0.0014243" ixy="3.9946E-05" ixz="4.7078E-06" iyy="0.00123" iyz="-0.00026073" izz="0.00099229"/></inertial><visual><origin rpy="0 0 0" xyz="0 0 0"/><geometry><!-- <mesh filename="package://xarm7_description/meshes/link1.STL" /> --><mesh filename="package://xarm7_description/meshes/link1.STL"/></geometry><material name="xarm7_White"/></visual><collision><origin rpy="0 0 0" xyz="0 0 0"/><geometry><!-- <mesh filename="package://xarm7_description/meshes/link1.STL" /> --><mesh filename="package://xarm7_description/meshes/link1.STL"/></geometry></collision></link><joint name="xarm7_joint1" type="revolute"><origin rpy="0 0 0" xyz="0 0 0.267"/><parent link="xarm7_link_base"/><child link="xarm7_link1"/><axis xyz="0 0 1"/><limit effort="50" lower="-6.283185307179586" upper="6.283185307179586" velocity="3.14"/><dynamics damping="10" friction="1"/></joint><link name="xarm7_link2"><inertial><origin rpy="0 0 0" xyz="-3.3178E-05 -0.12849 0.026337"/><mass value="0.56095"/><inertia ixx="0.0031915" ixy="3.0892E-06" ixz="2.8729E-06" iyy="0.0017468" iyz="-0.0010241" izz="0.00235"/></inertial><visual><origin rpy="0 0 0" xyz="0 0 0"/><geometry><!-- <mesh filename="package://xarm7_description/meshes/link2.STL" /> --><mesh filename="package://xarm7_description/meshes/link2.STL"/></geometry><material name="xarm7_White"/></visual><collision><origin rpy="0 0 0" xyz="0 0 0"/><geometry><!-- <mesh filename="package://xarm7_description/meshes/link2.STL" /> --><mesh filename="package://xarm7_description/meshes/link2.STL"/></geometry></collision></link><joint name="xarm7_joint2" type="revolute"><origin rpy="-1.5708 0 0" xyz="0 0 0"/><parent link="xarm7_link1"/><child link="xarm7_link2"/><axis xyz="0 0 1"/><limit effort="50" lower="-2.059" upper="2.0944" velocity="3.14"/><dynamics damping="10" friction="1"/></joint><link name="xarm7_link3"><inertial><origin rpy="0 0 0" xyz="0.04223 -0.023258 -0.0096674"/><mass value="0.44463"/><inertia ixx="0.0011454" ixy="0.0001654" ixz="-0.0001951" iyy="0.0010503" iyz="0.00012027" izz="0.0011083"/></inertial><visual><origin rpy="0 0 0" xyz="0 0 0"/><geometry><!-- <mesh filename="package://xarm7_description/meshes/link3.STL" /> --><mesh filename="package://xarm7_description/meshes/link3.STL"/></geometry><material name="xarm7_White"/></visual><collision><origin rpy="0 0 0" xyz="0 0 0"/><geometry><!-- <mesh filename="package://xarm7_description/meshes/link3.STL" /> --><mesh filename="package://xarm7_description/meshes/link3.STL"/></geometry></collision></link><joint name="xarm7_joint3" type="revolute"><origin rpy="1.5708 0 0" xyz="0 -0.293 0"/><parent link="xarm7_link2"/><child link="xarm7_link3"/><axis xyz="0 0 1"/><limit effort="30" lower="-6.283185307179586" upper="6.283185307179586" velocity="3.14"/><dynamics damping="5" friction="1"/></joint><link name="xarm7_link4"><inertial><origin rpy="0 0 0" xyz="0.067148 -0.10732 0.024479"/><mass value="0.52387"/><inertia ixx="0.0026033" ixy="0.00053379" ixz="0.00036314" iyy="0.0017649" iyz="-0.00083253" izz="0.0022431"/></inertial><visual><origin rpy="0 0 0" xyz="0 0 0"/><geometry><!-- <mesh filename="package://xarm7_description/meshes/link4.STL" /> --><mesh filename="package://xarm7_description/meshes/link4.STL"/></geometry><material name="xarm7_White"/></visual><collision><origin rpy="0 0 0" xyz="0 0 0"/><geometry><!-- <mesh filename="package://xarm7_description/meshes/link4.STL" /> --><mesh filename="package://xarm7_description/meshes/link4.STL"/></geometry></collision></link><joint name="xarm7_joint4" type="revolute"><origin rpy="1.5708 0 0" xyz="0.0525 0 0"/><parent link="xarm7_link3"/><child link="xarm7_link4"/><axis xyz="0 0 1"/><limit effort="30" lower="-0.19198" upper="3.927" velocity="3.14"/><dynamics damping="5" friction="1"/></joint><link name="xarm7_link5"><inertial><origin rpy="0 0 0" xyz="-0.00023397 0.036705 -0.080064"/><mass value="0.18554"/><inertia ixx="0.00099549" ixy="8.9957E-07" ixz="8.5285E-07" iyy="0.0008853" iyz="-0.00025682" izz="0.00035048"/></inertial><visual><origin rpy="0 0 0" xyz="0 0 0"/><geometry><!-- <mesh filename="package://xarm7_description/meshes/link5.STL" /> --><mesh filename="package://xarm7_description/meshes/link5.STL"/></geometry><material name="xarm7_White"/></visual><collision><origin rpy="0 0 0" xyz="0 0 0"/><geometry><!-- <mesh filename="package://xarm7_description/meshes/link5.STL" /> --><mesh filename="package://xarm7_description/meshes/link5.STL"/></geometry></collision></link><joint name="xarm7_joint5" type="revolute"><origin rpy="1.5708 0 0" xyz="0.0775 -0.3425 0"/><parent link="xarm7_link4"/><child link="xarm7_link5"/><axis xyz="0 0 1"/><limit effort="30" lower="-6.283185307179586" upper="6.283185307179586" velocity="3.14"/><dynamics damping="5" friction="1"/></joint><link name="xarm7_link6"><inertial><origin rpy="0 0 0" xyz="0.058911 0.028469 0.0068428"/><mass value="0.31344"/><inertia ixx="0.00052034" ixy="-0.00014989" ixz="0.00011658" iyy="0.00067968" iyz="6.116E-05" izz="0.00078345"/></inertial><visual><origin rpy="0 0 0" xyz="0 0 0"/><geometry><!-- <mesh filename="package://xarm7_description/meshes/link6.STL" /> --><mesh filename="package://xarm7_description/meshes/link6.STL"/></geometry><material name="xarm7_White"/></visual><collision><origin rpy="0 0 0" xyz="0 0 0"/><geometry><!-- <mesh filename="package://xarm7_description/meshes/link6.STL" /> --><mesh filename="package://xarm7_description/meshes/link6.STL"/></geometry></collision></link><joint name="xarm7_joint6" type="revolute"><origin rpy="1.5708 0 0" xyz="0 0 0"/><parent link="xarm7_link5"/><child link="xarm7_link6"/><axis xyz="0 0 1"/><limit effort="20" lower="-1.69297" upper="3.141592653589793" velocity="3.14"/><dynamics damping="2" friction="1"/></joint><link name="xarm7_link7"><inertial><origin rpy="0 0 0" xyz="-1.5846E-05 -0.0046377 -0.012705"/><mass value="0.31468"/><inertia ixx="0.00016985" ixy="1.1102E-07" ixz="5.1075E-08" iyy="0.00011924" iyz="-2.1251E-06" izz="0.00026032"/></inertial><visual><origin rpy="0 0 0" xyz="0 0 0"/><geometry><!-- <mesh filename="package://xarm7_description/meshes/link7.STL" /> --><mesh filename="package://xarm7_description/meshes/link7.STL"/></geometry><material name="xarm7_Silver"/></visual><collision><origin rpy="0 0 0" xyz="0 0 0"/><geometry><!-- <mesh filename="package://xarm7_description/meshes/link7.STL" /> --><mesh filename="package://xarm7_description/meshes/link7.STL"/></geometry></collision></link><joint name="xarm7_joint7" type="revolute"><origin rpy="-1.5708 0 0" xyz="0.076 0.097 0"/><parent link="xarm7_link6"/><child link="xarm7_link7"/><axis xyz="0 0 1"/><limit effort="20" lower="-6.283185307179586" upper="6.283185307179586" velocity="3.14"/><dynamics damping="2" friction="1"/></joint><link name="xarm7_camera_mount_link"><inertial><origin rpy="0 0 0" xyz="0 0 0"/><mass value="1.07263721378708"/><inertia ixx="8.81508739782784E-05" ixy="-2.27963379722004E-07" ixz="1.37753965258983E-05" iyy="0.000730776338756764" iyz="4.19702724954818E-07" izz="0.000754761139021083"/></inertial><visual><origin rpy="0.01 0 0" xyz="0 -0.072000000000001 0.02"/><geometry><mesh filename="package://xarm7_description/meshes/camera_mount.STL"/></geometry><material name=""><color rgba="0.752941176470588 0.752941176470588 0.752941176470588 1"/></material></visual><collision><origin rpy="0 0 0" xyz="0 -0.0675000000000001 0.0510499999999998"/><geometry><mesh filename="package://xarm7_description/meshes/camera_mount.STL"/></geometry></collision></link><joint name="xarm7_camera_mount_joint" type="revolute"><origin rpy="0 0 1.5707963267948966" xyz="0 0 0"/><parent link="xarm7_link7"/><child link="xarm7_camera_mount_link"/><axis xyz="0 0 -1"/><limit effort="0" lower="-6.2832" upper="6.2832" velocity="0"/></joint><joint name="xarm7_gripper_fix" type="fixed"><parent link="xarm7_camera_mount_link"/><child link="xarm7_xarm_gripper_base_link"/><origin rpy="0 0 -1.57075" xyz="0 0 0"/></joint><link name="xarm7_xarm_gripper_base_link"><inertial><origin rpy="0 0 0" xyz="-0.00065489 -0.0018497 0.048028"/><mass value="0.54156"/><inertia ixx="0.00047106" ixy="3.9292E-07" ixz="2.6537E-06" iyy="0.00033072" iyz="-1.0975E-05" izz="0.00025642"/></inertial><visual><geometry><mesh filename="package://xarm7_description/meshes/base_link.stl"/></geometry><origin rpy="0 0 0" xyz="0 0 0"/></visual><collision><geometry><mesh filename="package://xarm7_description/meshes/base_link.stl"/></geometry><origin rpy="0 0 0" xyz="0 0 0"/></collision></link><link name="xarm7_left_outer_knuckle"><inertial><origin rpy="0 0 0" xyz="2.9948E-14 0.021559 0.015181"/><mass value="0.033618"/><inertia ixx="1.9111E-05" ixy="-1.8803E-17" ixz="-1.1002E-17" iyy="6.6256E-06" iyz="-7.3008E-06" izz="1.3185E-05"/></inertial><visual><geometry><mesh filename="package://xarm7_description/meshes/left_outer_knuckle.stl"/></geometry><origin rpy="0 0 0" xyz="0 0 0"/></visual><collision><geometry><mesh filename="package://xarm7_description/meshes/left_outer_knuckle.stl"/></geometry><origin rpy="0 0 0" xyz="0 0 0"/></collision></link><joint name="xarm7_drive_joint" type="revolute"><origin rpy="0 0 0" xyz="0 0.035 0.059098"/><parent link="xarm7_xarm_gripper_base_link"/><child link="xarm7_left_outer_knuckle"/><axis xyz="1 0 0"/><limit effort="50" lower="0" upper="0.85" velocity="2"/></joint><link name="xarm7_left_finger"><inertial><origin rpy="0 0 0" xyz="-2.4536E-14 -0.016413 0.029258"/><mass value="0.048304"/><inertia ixx="1.7493E-05" ixy="-4.2156E-19" ixz="6.9164E-18" iyy="1.7225E-05" iyz="4.6433E-06" izz="5.1466E-06"/></inertial><visual><geometry><mesh filename="package://xarm7_description/meshes/left_finger.stl"/></geometry><origin rpy="0 0 0" xyz="0 0 0"/></visual><collision><geometry><mesh filename="package://xarm7_description/meshes/left_finger.stl"/></geometry><origin rpy="0 0 0" xyz="0 0 0"/></collision></link><joint name="xarm7_left_finger_joint" type="revolute"><origin rpy="0 0 0" xyz="0 0.035465 0.042039"/><parent link="xarm7_left_outer_knuckle"/><child link="xarm7_left_finger"/><axis xyz="-1 0 0"/><limit effort="50" lower="0" upper="0.85" velocity="2"/><mimic joint="xarm7_drive_joint" multiplier="1" offset="0"/></joint><link name="xarm7_left_inner_knuckle"><inertial><origin rpy="0 0 0" xyz="1.86600784687907E-06 0.0220467847633621 0.0261334672830885"/><mass value="0.0230125781256706"/><inertia ixx="6.09490024271906E-06" ixy="6.06651326160071E-11" ixz="7.19102670500635E-11" iyy="6.01955084375188E-06" iyz="-2.75316812991721E-06" izz="5.07862004479903E-06"/></inertial><visual><geometry><mesh filename="package://xarm7_description/meshes/left_inner_knuckle.stl"/></geometry><origin rpy="0 0 0" xyz="0 0 0"/></visual><collision><geometry><mesh filename="package://xarm7_description/meshes/left_inner_knuckle.stl"/></geometry><origin rpy="0 0 0" xyz="0 0 0"/></collision></link><joint name="xarm7_left_inner_knuckle_joint" type="revolute"><origin rpy="0 0 0" xyz="0 0.02 0.074098"/><parent link="xarm7_xarm_gripper_base_link"/><child link="xarm7_left_inner_knuckle"/><axis xyz="1 0 0"/><limit effort="50" lower="0" upper="0.85" velocity="2"/><mimic joint="xarm7_drive_joint" multiplier="1" offset="0"/></joint><link name="xarm7_right_outer_knuckle"><inertial><origin rpy="0 0 0" xyz="-3.1669E-14 -0.021559 0.015181"/><mass value="0.033618"/><inertia ixx="1.9111E-05" ixy="-1.8789E-17" ixz="1.0986E-17" iyy="6.6256E-06" iyz="7.3008E-06" izz="1.3185E-05"/></inertial><visual><geometry><mesh filename="package://xarm7_description/meshes/right_outer_knuckle.stl"/></geometry><origin rpy="0 0 0" xyz="0 0 0"/></visual><collision><geometry><mesh filename="package://xarm7_description/meshes/right_outer_knuckle.stl"/></geometry><origin rpy="0 0 0" xyz="0 0 0"/></collision></link><joint name="xarm7_right_outer_knuckle_joint" type="revolute"><origin rpy="0 0 0" xyz="0 -0.035 0.059098"/><parent link="xarm7_xarm_gripper_base_link"/><child link="xarm7_right_outer_knuckle"/><axis xyz="-1 0 0"/><limit effort="50" lower="0" upper="0.85" velocity="2"/><mimic joint="xarm7_drive_joint" multiplier="1" offset="0"/></joint><link name="xarm7_right_finger"><inertial><origin rpy="0 0 0" xyz="2.5618E-14 0.016413 0.029258"/><mass value="0.048304"/><inertia ixx="1.7493E-05" ixy="-5.0014E-19" ixz="-7.5079E-18" iyy="1.7225E-05" iyz="-4.6435E-06" izz="5.1466E-06"/></inertial><visual><geometry><mesh filename="package://xarm7_description/meshes/right_finger.stl"/></geometry><origin rpy="0 0 0" xyz="0 0 0"/></visual><collision><geometry><mesh filename="package://xarm7_description/meshes/right_finger.stl"/></geometry><origin rpy="0 0 0" xyz="0 0 0"/></collision></link><joint name="xarm7_right_finger_joint" type="revolute"><origin rpy="0 0 0" xyz="0 -0.035465 0.042039"/><parent link="xarm7_right_outer_knuckle"/><child link="xarm7_right_finger"/><axis xyz="1 0 0"/><limit effort="50" lower="0" upper="0.85" velocity="2"/><mimic joint="xarm7_drive_joint" multiplier="1" offset="0"/></joint><link name="xarm7_right_inner_knuckle"><inertial><origin rpy="0 0 0" xyz="1.866E-06 -0.022047 0.026133"/><mass value="0.023013"/><inertia ixx="6.0949E-06" ixy="-6.0665E-11" ixz="7.191E-11" iyy="6.0197E-06" iyz="2.7531E-06" izz="5.0784E-06"/></inertial><visual><geometry><mesh filename="package://xarm7_description/meshes/right_inner_knuckle.stl"/></geometry><origin rpy="0 0 0" xyz="0 0 0"/></visual><collision><geometry><mesh filename="package://xarm7_description/meshes/right_inner_knuckle.stl"/></geometry><origin rpy="0 0 0" xyz="0 0 0"/></collision></link><joint name="xarm7_right_inner_knuckle_joint" type="revolute"><origin rpy="0 0 0" xyz="0 -0.02 0.074098"/><parent link="xarm7_xarm_gripper_base_link"/><child link="xarm7_right_inner_knuckle"/><axis xyz="-1 0 0"/><limit effort="50" lower="0" upper="0.85" velocity="2"/><mimic joint="xarm7_drive_joint" multiplier="1" offset="0"/></joint><link name="xarm7_link_tcp"/><joint name="xarm7_joint_tcp" type="fixed"><origin rpy="0 0 0" xyz="0 0 0.172"/><parent link="xarm7_xarm_gripper_base_link"/><child link="xarm7_link_tcp"/></joint><!-- camera body, with origin at bottom screw mount --><joint name="d455_joint" type="fixed"><origin rpy=" 0 -1.57 1.57 " xyz="-0.05 -0.07 0.02"/><parent link="xarm7_camera_mount_link"/><child link="d455_link"/></joint><link name="d455_link"><visual><!-- the mesh origin is at front plate in between the two infrared camera axes --><!-- <origin xyz="${d455_zero_depth_to_glass-d455_cam_depth/2} ${-d455_cam_depth_py} 0" rpy="0 0 0"/> --><origin rpy="1.5707963267948966 0 1.5707963267948966" xyz="0.0046500000000000005 -0.0475 0"/><geometry><!-- <box size="${d455_cam_depth} ${d455_cam_width} ${d455_cam_height}"/> --><mesh filename="package://xarm7_description/meshes/d455.STL" scale="0.001 0.001 0.001"/></geometry><material name="aluminum"/></visual><collision><origin rpy="0 0 0" xyz="-0.00845 -0.0475 0"/><geometry><box size="0.026 0.124 0.029"/></geometry></collision><inertial><origin xyz="0 0 0"/><mass value="0.072"/><inertia ixx="9.730199999999998e-05" ixy="0.0" ixz="0.0" iyy="9.102e-06" iyz="0.0" izz="9.6312e-05"/></inertial></link><!-- camera depth joints and links --><joint name="d455_depth_joint" type="fixed"><origin rpy="0 0 0" xyz="0 0 0"/><parent link="d455_link"/><child link="d455_depth_frame"/></joint><link name="d455_depth_frame"/><joint name="d455_depth_optical_joint" type="fixed"><origin rpy="-1.5707963267948966 0 -1.5707963267948966" xyz="0 0 0"/><parent link="d455_depth_frame"/><child link="d455_depth_optical_frame"/></joint><link name="d455_depth_optical_frame"/><!-- camera left IR joints and links --><joint name="d455_infra1_joint" type="fixed"><origin rpy="0 0 0" xyz="0 0.0 0"/><parent link="d455_link"/><child link="d455_infra1_frame"/></joint><link name="d455_infra1_frame"/><joint name="d455_infra1_optical_joint" type="fixed"><origin rpy="-1.5707963267948966 0 -1.5707963267948966" xyz="0 0 0"/><parent link="d455_infra1_frame"/><child link="d455_infra1_optical_frame"/></joint><link name="d455_infra1_optical_frame"/><!-- camera right IR joints and links --><joint name="d455_infra2_joint" type="fixed"><origin rpy="0 0 0" xyz="0 -0.095 0"/><parent link="d455_link"/><child link="d455_infra2_frame"/></joint><link name="d455_infra2_frame"/><joint name="d455_infra2_optical_joint" type="fixed"><origin rpy="-1.5707963267948966 0 -1.5707963267948966" xyz="0 0 0"/><parent link="d455_infra2_frame"/><child link="d455_infra2_optical_frame"/></joint><link name="d455_infra2_optical_frame"/><!-- camera color joints and links --><joint name="d455_color_joint" type="fixed"><origin rpy="0 0 0" xyz="0 -0.059 0"/><parent link="d455_link"/><child link="d455_color_frame"/></joint><link name="d455_color_frame"/><joint name="d455_color_optical_joint" type="fixed"><origin rpy="0.0 1.5707963267948966 0.0" xyz="0 0 0"/><parent link="d455_color_frame"/><child link="d455_color_optical_frame"/></joint><link name="d455_color_optical_frame"/><link name="d455_accel_frame"/><link name="d455_accel_optical_frame"/><link name="d455_gyro_frame"/><link name="d455_gyro_optical_frame"/><link name="d455_imu_optical_frame"/><joint name="d455_accel_joint" type="fixed"><origin rpy="0 0 0" xyz="-0.01602 -0.03022 0.0074"/><parent link="d455_link"/><child link="d455_accel_frame"/></joint><joint name="d455_accel_optical_joint" type="fixed"><origin rpy="-1.5707963267948966 0 -1.5707963267948966" xyz="0 0 0"/><parent link="d455_accel_frame"/><child link="d455_accel_optical_frame"/></joint><joint name="d455_gyro_joint" type="fixed"><origin rpy="0 0 0" xyz="-0.01602 -0.03022 0.0074"/><parent link="d455_link"/><child link="d455_gyro_frame"/></joint><joint name="d455_gyro_optical_joint" type="fixed"><origin rpy="-1.5707963267948966 0 -1.5707963267948966" xyz="0 0 0"/><parent link="d455_gyro_frame"/><child link="d455_gyro_optical_frame"/></joint><joint name="d455_imu_optical_joint" type="fixed"><origin rpy="0 0 0" xyz="0 0 0"/><parent link="d455_gyro_optical_frame"/><child link="d455_imu_optical_frame"/></joint><ros2_control name="xarm7" type="system"><hardware><plugin>isaac_hardware/IsaacDriveHardware</plugin><param name="example_param_hw_start_duration_sec">3.0</param><param name="example_param_hw_stop_duration_sec">3.0</param></hardware><joint name="xarm7_joint1"><command_interface name="velocity"><param name="min">-10</param><param name="max">10</param></command_interface><state_interface name="position"/><state_interface name="velocity"/></joint><joint name="xarm7_joint2"><command_interface name="velocity"><param name="min">-10</param><param name="max">10</param></command_interface><state_interface name="position"/><state_interface name="velocity"/></joint><joint name="xarm7_joint3"><command_interface name="velocity"><param name="min">-10</param><param name="max">10</param></command_interface><state_interface name="position"/><state_interface name="velocity"/></joint><joint name="xarm7_joint4"><command_interface name="velocity"><param name="min">-10</param><param name="max">10</param></command_interface><state_interface name="position"/><state_interface name="velocity"/></joint><joint name="xarm7_joint5"><command_interface name="velocity"><param name="min">-10</param><param name="max">10</param></command_interface><state_interface name="position"/><state_interface name="velocity"/></joint><joint name="xarm7_joint6"><command_interface name="velocity"><param name="min">-10</param><param name="max">10</param></command_interface><state_interface name="position"/><state_interface name="velocity"/></joint><joint name="xarm7_joint7"><command_interface name="velocity"><param name="min">-10</param><param name="max">10</param></command_interface><state_interface name="position"/><state_interface name="velocity"/></joint><joint name="xarm7_camera_mount_joint"><command_interface name="velocity"><param name="min">-10</param><param name="max">10</param></command_interface><state_interface name="position"/><state_interface name="velocity"/></joint><joint name="xarm7_end_effector_joint"><command_interface name="position"><param name="min">0</param><param name="max">10</param></command_interface><state_interface name="position"/><state_interface name="velocity"/></joint><joint name="xarm7_drive_joint"><command_interface name="position">
                </command_interface><command_interface name="velocity"><param name="min">-3.14</param><param name="max">3.14</param></command_interface><state_interface name="position"/><state_interface name="velocity"/><!-- <state_interface name="effort"/> --></joint></ros2_control></robot>